---
title: "C6318 | Microsoft Docs"
ms.custom: ""
ms.date: "12/05/2016"
ms.prod: "visual-studio-dev14"
ms.reviewer: ""
ms.suite: ""
ms.technology: 
  - "vs-devops-test"
ms.tgt_pltfrm: ""
ms.topic: "article"
f1_keywords: 
  - "C6318"
helpviewer_keywords: 
  - "C6318"
ms.assetid: 3284a83e-bb8e-461c-adcc-cfc66ceea05e
caps.latest.revision: 13
caps.handback.revision: 13
author: "corob-msft"
ms.author: "corob"
manager: "ghogen"
---
# C6318
[!INCLUDE[vs2017banner](../code-quality/includes/vs2017banner.md)]

Предупреждение C6318: неверное определение \_\_try\/\_\_except. Использование EXCEPTION\_CONTINUE\_SEARCH или другой константы с нулевым результатом в выражении фильтра исключений.  Код в блоке обработки исключений не выполняется.  
  
 Это предупреждение указывает, что при возникновении исключения в защищенном блоке данного обработчика структурированных исключений это исключение не будет обработано, поскольку в выражении фильтра исключений используется константа `EXCECPTION_CONTINUE_SEARCH`.  
  
 Этот код эквивалентен защищенному блоку без блока обработки исключений, поскольку блок обработки не выполняется.  
  
## Пример  
 Данное предупреждение создается в следующем коде:  
  
```  
#include <excpt.h>  
#include <stdio.h>  
  
void f (char *pch)  
{  
  __try   
  {  
    // assignment might fail  
    *pch = 0;  
  }   
  __except (EXCEPTION_CONTINUE_SEARCH) // warning 6318  
  {  
    puts("Exception Occurred");  
  }  
}  
```  
  
 Для устранения этого предупреждения используйте следующий код:  
  
```  
#include <excpt.h>  
#include <stdio.h>  
#include <windows.h>  
  
void f (char *pch)  
{  
  __try   
  {  
    // assignment might fail  
    *pch = 0;  
  }   
  __except( (GetExceptionCode() == EXCEPTION_ACCESS_VIOLATION) ?  
                EXCEPTION_EXECUTE_HANDLER : EXCEPTION_CONTINUE_SEARCH )  
  {  
    puts("Access violation");  
  }  
}   
```  
  
## См. также  
 [Оператор try\-except](/visual-cpp/cpp/try-except-statement)